Workbook

Sheet Overview
A1: PriModel Scoring Engine
A2: Parametrized Lookup Tables and Scoring Specification
A4: This workbook contains the complete scoring specification for PriModel, the recommendation engine that helps lounge staff decide which waitlisted group to call next.
A5: Each raw operational variable is converted into a normalized score (0-100) via parametrized lookup tables. Scores are stable and predictable: the same input always produces the same score, regardless of queue composition.
A7: Tab | B7: Content
A8: Dimensions | B8: The four scoring dimensions, how they combine, and key design principles
A9: Variables | B9: All 16 input variables with type (Raw/Derived), source, availability, and which lookup table each feeds
A10: Normalization | B10: Why parametrized lookup tables (not relative normalization), with comparison and concrete example
A11: Data Flow | B11: End-to-end flow from front-end capture to suggestion cards in 5 stages, with full Group A walkthrough and 3-group comparison
A12: LT-Capacity | B12: Party size and estimated stay lookup tables, composite formula, occupancy pressure modifier
A13: LT-Fairness | B13: Wait time and consecutive skips lookup tables, composite formula
A14: LT-Urgency | B14: Time to departure lookup table (no taper), flight status modifier
A15: LT-Revenue | B15: Value per person lookup table, revenue waterfall, and missing data behavior
A16: Weights | B16: 4 optimization modes with weight configurations
A17: Hard Overrides | B17: Binary rules that bypass scoring (Max Wait, Starvation Guard, Flight Departed, Program Cap)
A18: Data Degradation | B18: What happens when variables are missing, impact by dimension, Revenue missing worked example
A19: Worked Example | B19: 3 full scoring walkthroughs: Scenario 1 (Capacity wins), Scenario 2 (Fairness wins), Scenario 4 (Revenue Focus)

Sheet Exemples - Real use cases
A1: WORKED EXAMPLE - Scenario 1: Capacity Efficiency Beats Raw Revenue
A2: 3:20 PM. 3 seats available. Balanced mode. Full scoring walkthrough.
A4: Step 1: Raw Data (Front-End)
A5: Group | B5: Program | C5: Party Size | D5: Wait (min) | E5: Flight | F5: TTD (min) | G5: Est. Stay (min) | H5: Value/pp
A6: A | B6: Priority Pass | C6: 1 | D6: 15 | E6: 4:10 PM | F6: 50 | G6: 20 | H6: $27
A7: B | B7: Amex Platinum | C7: 2 | D7: 10 | E7: 5:20 PM | F7: 120 | G7: 90 | H7: $25
A8: C | B8: LoungeKey | C8: 3 | D8: 5 | E8: 6:20 PM | F8: 180 | G8: 150 | H8: $24
A10: Step 2: Lookup Table Normalization (Back-End)
A11: Group | B11: PartySize Score | C11: EstStay Score | D11: Capacity Score | E11: Wait Score | F11: Skips Score | G11: Fairness Score | H11: TTD Score (Urgency) | I11: Value Score (Revenue)
A12: A | B12: 100 | C12: 100 | D12: (100*0.4+100*0.6)=100 | E12: 30 | F12: 0 | G12: (30*0.6+0*0.4)=18 | H12: 80 | I12: 80
A13: B | B13: 85 | C13: 55 | D13: (85*0.4+55*0.6)=67 | E13: 20 | F13: 0 | G13: (20*0.6+0*0.4)=12 | H13: 45 | I13: 70
A14: C | B14: 70 | C14: 15 | D14: (70*0.4+15*0.6)=37 | E14: 10 | F14: 0 | G14: (10*0.6+0*0.4)=6 | H14: 0 | I14: 60
A17: Step 3: Weighted Composite Score (Balanced Mode: R=0.25, C=0.25, F=0.30, U=0.20)
A18: Group | B18: Revenue (x0.25) | C18: Capacity (x0.25) | D18: Fairness (x0.30) | E18: Urgency (x0.20) | F18: PriModelScore | G18: Rank
A19: A | B19: 80*0.25=20.0 | C19: 100*0.25=25.0 | D19: 18*0.30=5.4 | E19: 80*0.20=16.0 | F19: 66.4 | G19: #1
A20: B | B20: 70*0.25=17.5 | C20: 67*0.25=16.8 | D20: 12*0.30=3.6 | E20: 45*0.20=9.0 | F20: 46.9 | G20: #2
A21: C | B21: 60*0.25=15.0 | C21: 37*0.25=9.3 | D21: 6*0.30=1.8 | E21: 0*0.20=0.0 | F21: 26.1 | G21: #3
A23: Result: Group A scores 66.4, Group B 46.9, Group C 26.1.
A24: Group A wins by 19.5 points over B and 40.3 points over C. Decisive, not marginal.
A25: Capacity (25.0 vs 9.3) and Urgency (16.0 vs 0.0) are the dominant differentiators.
A26: Revenue favors C ($72 total) over A ($27 total), but only contributes 5 points of difference. Cannot overcome a 56-point capacity+urgency gap.
A29: WORKED EXAMPLE - Scenario 2: Fairness Protects Long-Waiting Passengers
A30: 4 seats available. Balanced mode. Fairness dominates.
A32: Step 1: Raw Data
A33: Group | B33: Program | C33: Party | D33: Wait (min) | E33: TTD (min) | F33: Est. Stay | G33: Value/pp | H33: Skips
A34: C | B34: LoungeKey | C34: 1 | D34: 40 | E34: 180 | F34: 150 | G34: $24 | H34: 5
A35: A | B35: Priority Pass | C35: 2 | D35: 35 | E35: 60 | F35: 30 | G35: $27 | H35: 4
A36: B | B36: Amex Platinum | C36: 4 | D36: 5 | E36: 120 | F36: 90 | G36: $25 | H36: 0
A38: Step 2: Lookup Table Normalization
A39: Group | B39: Capacity | C39: Fairness | D39: Urgency | E39: Revenue
A40: C | B40: (100x0.4)+(15x0.6) = 49 | C40: (80x0.6)+(65x0.4) = 74 | D40: 0 (180+ min) | E40: 60 ($24)
A41: A | B41: (85x0.4)+(85x0.6) = 85 | C41: (70x0.6)+(55x0.4) = 64 | D41: 80 (46-60 min) | E41: 80 ($27)
A42: B | B42: (55x0.4)+(55x0.6) = 55 | C42: (10x0.6)+(0x0.4) = 6 | D42: 45 (91-120 min) | E42: 70 ($25)
A44: Step 3: Weighted Composite (Balanced: R=0.25, C=0.25, F=0.30, U=0.20)
A45: Group | B45: Revenue (x0.25) | C45: Capacity (x0.25) | D45: Fairness (x0.30) | E45: Urgency (x0.20) | F45: PriModelScore | G45: Rank
A46: A | B46: 80x0.25=20.0 | C46: 85x0.25=21.3 | D46: 64x0.30=19.2 | E46: 80x0.20=16.0 | F46: 76.5 | G46: #1
A47: C | B47: 60x0.25=15.0 | C47: 49x0.25=12.3 | D47: 74x0.30=22.2 | E47: 0x0.20=0.0 | F47: 49.5 | G47: #2
A48: B | B48: 70x0.25=17.5 | C48: 55x0.25=13.8 | D48: 6x0.30=1.8 | E48: 45x0.20=9.0 | F48: 42.1 | G48: #3
A50: Group A wins: Fairness (19.2) + Urgency (16.0) overcome B's revenue advantage. Group B at $100 total ranks #3 because 5 min wait = Fairness score of 6.
A53: WORKED EXAMPLE - Scenario 4: Revenue Optimization (Revenue Focus Mode)
...

Sheet Simulation v.2
A1: Front End (Simplified — 3 Variables) | I1: Back End — 3 Dimension Scores | O1: Selected Model | P1: Balanced | Q1: Result | T1: Scores by Model | AA1: PartySize | AB1: CapScore | AD1: EstStay_Max | AE1: StayScore | AG1: TTD_Max | AH1: TTDScore | AJ1: Wait_Max | AK1: WaitScore | AM1: Skips | AN1: SkipScore | AP1: AccessProgram | AQ1: Value_pp | AR1: RevScore | AT1: Model | AU1: W1_Capacity | AV1: W2_Fairness | AW1: W3_Urgency | AZ1: Group | BA1: Balanced | BB1: Revenue Focus | BC1: Efficiency Focus | BD1: Fairness First
A2: waitlist_id | B2: party_size | C2: time_to_departure_min | D2: wait_time_min | I2: waitlist_id | J2: Capacity Score | K2: Fairness Score | L2: Urgency Score | M2: PriModelScore | O2: Occupancy Level | P2: Medium | Q2: Final Score | R2: Rank | T2: Group | U2: Balanced | V2: Revenue Focus | W2: Efficiency Focus | X2: Fairness First | AA2: 1 | AB2: 100 | AD2: 20 | AE2: 100 | AG2: 15 | AH2: 100 | AJ2: 5 | AK2: 10 | AM2: 0 | AN2: 0 | AP2: Priority Pass | AQ2: 27 | AR2: 80 | AT2: Balanced | AU2: 0.35 | AV2: 0.3 | AW2: 0.35 | AZ2: ="G"&T3 -> G1 | BA2: =U3 -> 75.5 | BB2: =V3 -> 80 | BC2: =W3 -> 86 | BD2: =X3 -> 59
A3: 1 | B3: 1 | C3: 50 | D3: 15 | I3: =A3 -> 1 | J3: =MIN(100,IFERROR(VLOOKUP(B3,AA2:AB7,2,FALSE),IF(B3>=6,25,50))*$P$9) -> 100 | K3: =VLOOKUP(D3,AJ2:AK12,2,TRUE) -> 30 | L3: =VLOOKUP(C3,AG2:AH10,2,TRUE) -> 90 | M3: =($P$4*J3)+($P$5*K3)+($P$6*L3) -> 75.5 | Q3: =IF(D3>60,999,M3) -> 75.5 | R3: =RANK(Q3,$Q$3:$Q$8,0) -> 2 | T3: =A3 -> 1 | U3: =IF(D3>60,999,(INDEX(AT2:AW5,MATCH("Balanced",AT2:AT5,0),2)*J3)+(INDEX(AT2:AW5,MATCH("Balanced",AT2:AT5,0),3)*K3)+(INDEX(AT2:AW5,MATCH("Balanced",AT2:AT5,0),4)*L3)) -> 75.5 | V3: =IF(D3>60,999,(INDEX(AT2:AW5,MATCH("Revenue Focus",AT2:AT5,0),2)*J3)+(INDEX(AT2:AW5,MATCH("Revenue Focus",AT2:AT5,0),3)*K3)+(INDEX(AT2:AW5,MATCH("Revenue Focus",AT2:AT5,0),4)*L3)) -> 80 | W3: =IF(D3>60,999,(INDEX(AT2:AW5,MATCH("Efficiency Focus",AT2:AT5,0),2)*J3)+(INDEX(AT2:AW5,MATCH("Efficiency Focus",AT2:AT5,0),3)*K3)+(INDEX(AT2:AW5,MATCH("Efficiency Focus",AT2:AT5,0),4)*L3)) -> 86 | X3: =IF(D3>60,999,(INDEX(AT2:AW5,MATCH("Fairness First",AT2:AT5,0),2)*J3)+(INDEX(AT2:AW5,MATCH("Fairness First",AT2:AT5,0),3)*K3)+(INDEX(AT2:AW5,MATCH("Fairness First",AT2:AT5,0),4)*L3)) -> 59 | AA3: 2 | AB3: 85 | AD3: 40 | AE3: 85 | AG3: 30 | AH3: 95 | AJ3: 10 | AK3: 20 | AM3: 1 | AN3: 15 | AP3: LoungeKey | AQ3: 24 | AR3: 60 | AT3: Revenue Focus | AU3: 0.2 | AV3: 0.2 | AW3: 0.6 | AZ3: ="G"&T4 -> G2 | BA3: =U4 -> 51.5 | BB3: =V4 -> 48 | BC3: =W4 -> 61.25 | BD3: =X4 -> 39.25
A4: 2 | B4: 2 | C4: 120 | D4: 10 | F4: → | H4: → | I4: =A4 -> 2 | J4: =MIN(100,IFERROR(VLOOKUP(B4,AA2:AB7,2,FALSE),IF(B4>=6,25,50))*$P$9) -> 85 | K4: =VLOOKUP(D4,AJ2:AK12,2,TRUE) -> 20 | L4: =VLOOKUP(C4,AG2:AH10,2,TRUE) -> 45 | M4: =($P$4*J4)+($P$5*K4)+($P$6*L4) -> 51.5 | N4: → | O4: W1 Capacity | P4: =VLOOKUP($P$1,AT2:AW5,2,FALSE) -> 0.35 | Q4: =IF(D4>60,999,M4) -> 51.5 | R4: =RANK(Q4,$Q$3:$Q$8,0) -> 4 | T4: =A4 -> 2 | U4: =IF(D4>60,999,(INDEX(AT2:AW5,MATCH("Balanced",AT2:AT5,0),2)*J4)+(INDEX(AT2:AW5,MATCH("Balanced",AT2:AT5,0),3)*K4)+(INDEX(AT2:AW5,MATCH("Balanced",AT2:AT5,0),4)*L4)) -> 51.5 | V4: =IF(D4>60,999,(INDEX(AT2:AW5,MATCH("Revenue Focus",AT2:AT5,0),2)*J4)+(INDEX(AT2:AW5,MATCH("Revenue Focus",AT2:AT5,0),3)*K4)+(INDEX(AT2:AW5,MATCH("Revenue Focus",AT2:AT5,0),4)*L4)) -> 48 | W4: =IF(D4>60,999,(INDEX(AT2:AW5,MATCH("Efficiency Focus",AT2:AT5,0),2)*J4)+(INDEX(AT2:AW5,MATCH("Efficiency Focus",AT2:AT5,0),3)*K4)+(INDEX(AT2:AW5,MATCH("Efficiency Focus",AT2:AT5,0),4)*L4)) -> 61.25 | X4: =IF(D4>60,999,(INDEX(AT2:AW5,MATCH("Fairness First",AT2:AT5,0),2)*J4)+(INDEX(AT2:AW5,MATCH("Fairness First",AT2:AT5,0),3)*K4)+(INDEX(AT2:AW5,MATCH("Fairness First",AT2:AT5,0),4)*L4)) -> 39.25 | AA4: 3 | AB4: 70 | AD4: 60 | AE4: 70 | AG4: 45 | AH4: 90 | AJ4: 15 | AK4: 30 | AM4: 2 | AN4: 30 | AP4: Amex Platinum | AQ4: 25 | AR4: 70 | AT4: Efficiency Focus | AU4: 0.5 | AV4: 0.15 | AW4: 0.35 | AZ4: ="G"&T5 -> G3 | BA4: =U5 -> 31 | BB4: =V5 -> 22 | BC4: =W5 -> 40 | BD4: =X5 -> 22
A5: 3 | B5: 3 | C5: 180 | D5: 5 | I5: =A5 -> 3 | J5: =MIN(100,IFERROR(VLOOKUP(B5,AA2:AB7,2,FALSE),IF(B5>=6,25,50))*$P$9) -> 70 | K5: =VLOOKUP(D5,AJ2:AK12,2,TRUE) -> 10 | L5: =VLOOKUP(C5,AG2:AH10,2,TRUE) -> 10 | M5: =($P$4*J5)+($P$5*K5)+($P$6*L5) -> 31 | O5: W2 Fairness | P5: =VLOOKUP($P$1,AT2:AW5,3,FALSE) -> 0.3 | Q5: =IF(D5>60,999,M5) -> 31 | R5: =RANK(Q5,$Q$3:$Q$8,0) -> 6 | T5: =A5 -> 3 | U5: =IF(D5>60,999,(INDEX(AT2:AW5,MATCH("Balanced",AT2:AT5,0),2)*J5)+(INDEX(AT2:AW5,MATCH("Balanced",AT2:AT5,0),3)*K5)+(INDEX(AT2:AW5,MATCH("Balanced",AT2:AT5,0),4)*L5)) -> 31 | V5: =IF(D5>60,999,(INDEX(AT2:AW5,MATCH("Revenue Focus",AT2:AT5,0),2)*J5)+(INDEX(AT2:AW5,MATCH("Revenue Focus",AT2:AT5,0),3)*K5)+(INDEX(AT2:AW5,MATCH("Revenue Focus",AT2:AT5,0),4)*L5)) -> 22 | W5: =IF(D5>60,999,(INDEX(AT2:AW5,MATCH("Efficiency Focus",AT2:AT5,0),2)*J5)+(INDEX(AT2:AW5,MATCH("Efficiency Focus",AT2:AT5,0),3)*K5)+(INDEX(AT2:AW5,MATCH("Efficiency Focus",AT2:AT5,0),4)*L5)) -> 40 | X5: =IF(D5>60,999,(INDEX(AT2:AW5,MATCH("Fairness First",AT2:AT5,0),2)*J5)+(INDEX(AT2:AW5,MATCH("Fairness First",AT2:AT5,0),3)*K5)+(INDEX(AT2:AW5,MATCH("Fairness First",AT2:AT5,0),4)*L5)) -> 22 | AA5: 4 | AB5: 55 | AD5: 90 | AE5: 55 | AG5: 60 | AH5: 80 | AJ5: 20 | AK5: 40 | AM5: 3 | AN5: 45 | AP5: Day Pass (walk-in) | AQ5: 35 | AR5: 100 | AT5: Fairness First | AU5: 0.2 | AV5: 0.55 | AW5: 0.25 | AZ5: ="G"&T6 -> G4 | BA5: =U6 -> 68.25 | BB5: =V6 -> 73 | BC5: =W6 -> 66 | BD5: =X6 -> 69.5
A6: 4 | B6: 4 | C6: 89 | D6: 35 | I6: =A6 -> 4 | J6: =MIN(100,IFERROR(VLOOKUP(B6,AA2:AB7,2,FALSE),IF(B6>=6,25,50))*$P$9) -> 55 | K6: =VLOOKUP(D6,AJ2:AK12,2,TRUE) -> 70 | L6: =VLOOKUP(C6,AG2:AH10,2,TRUE) -> 80 | M6: =($P$4*J6)+($P$5*K6)+($P$6*L6) -> 68.25 | O6: W3 Urgency | P6: =VLOOKUP($P$1,AT2:AW5,4,FALSE) -> 0.35 | Q6: =IF(D6>60,999,M6) -> 68.25 | R6: =RANK(Q6,$Q$3:$Q$8,0) -> 3 | T6: =A6 -> 4 | U6: =IF(D6>60,999,(INDEX(AT2:AW5,MATCH("Balanced",AT2:AT5,0),2)*J6)+(INDEX(AT2:AW5,MATCH("Balanced",AT2:AT5,0),3)*K6)+(INDEX(AT2:AW5,MATCH("Balanced",AT2:AT5,0),4)*L6)) -> 68.25 | V6: =IF(D6>60,999,(INDEX(AT2:AW5,MATCH("Revenue Focus",AT2:AT5,0),2)*J6)+(INDEX(AT2:AW5,MATCH("Revenue Focus",AT2:AT5,0),3)*K6)+(INDEX(AT2:AW5,MATCH("Revenue Focus",AT2:AT5,0),4)*L6)) -> 73 | W6: =IF(D6>60,999,(INDEX(AT2:AW5,MATCH("Efficiency Focus",AT2:AT5,0),2)*J6)+(INDEX(AT2:AW5,MATCH("Efficiency Focus",AT2:AT5,0),3)*K6)+(INDEX(AT2:AW5,MATCH("Efficiency Focus",AT2:AT5,0),4)*L6)) -> 66 | X6: =IF(D6>60,999,(INDEX(AT2:AW5,MATCH("Fairness First",AT2:AT5,0),2)*J6)+(INDEX(AT2:AW5,MATCH("Fairness First",AT2:AT5,0),3)*K6)+(INDEX(AT2:AW5,MATCH("Fairness First",AT2:AT5,0),4)*L6)) -> 69.5 | AA6: 5 | AB6: 40 | AD6: 120 | AE6: 40 | AG6: 90 | AH6: 65 | AJ6: 25 | AK6: 50 | AM6: 4 | AN6: 55 | AZ6: ="G"&T7 -> G5 | BA6: =U7 -> 88.75 | BB6: =V7 -> 93 | BC6: =W7 -> 89.5 | BD6: =X7 -> 86
A7: 5 | B7: 2 | C7: 25 | D7: 40 | I7: =A7 -> 5 | J7: =MIN(100,IFERROR(VLOOKUP(B7,AA2:AB7,2,FALSE),IF(B7>=6,25,50))*$P$9) -> 85 | K7: =VLOOKUP(D7,AJ2:AK12,2,TRUE) -> 80 | L7: =VLOOKUP(C7,AG2:AH10,2,TRUE) -> 100 | M7: =($P$4*J7)+($P$5*K7)+($P$6*L7) -> 88.75 | Q7: =IF(D7>60,999,M7) -> 88.75 | R7: =RANK(Q7,$Q$3:$Q$8,0) -> 1 | T7: =A7 -> 5 | U7: =IF(D7>60,999,(INDEX(AT2:AW5,MATCH("Balanced",AT2:AT5,0),2)*J7)+(INDEX(AT2:AW5,MATCH("Balanced",AT2:AT5,0),3)*K7)+(INDEX(AT2:AW5,MATCH("Balanced",AT2:AT5,0),4)*L7)) -> 88.75 | V7: =IF(D7>60,999,(INDEX(AT2:AW5,MATCH("Revenue Focus",AT2:AT5,0),2)*J7)+(INDEX(AT2:AW5,MATCH("Revenue Focus",AT2:AT5,0),3)*K7)+(INDEX(AT2:AW5,MATCH("Revenue Focus",AT2:AT5,0),4)*L7)) -> 93 | W7: =IF(D7>60,999,(INDEX(AT2:AW5,MATCH("Efficiency Focus",AT2:AT5,0),2)*J7)+(INDEX(AT2:AW5,MATCH("Efficiency Focus",AT2:AT5,0),3)*K7)+(INDEX(AT2:AW5,MATCH("Efficiency Focus",AT2:AT5,0),4)*L7)) -> 89.5 | X7: =IF(D7>60,999,(INDEX(AT2:AW5,MATCH("Fairness First",AT2:AT5,0),2)*J7)+(INDEX(AT2:AW5,MATCH("Fairness First",AT2:AT5,0),3)*K7)+(INDEX(AT2:AW5,MATCH("Fairness First",AT2:AT5,0),4)*L7)) -> 86 | AA7: 6 | AB7: 25 | AD7: 150 | AE7: 25 | AG7: 120 | AH7: 45 | AJ7: 30 | AK7: 60 | AM7: 5 | AN7: 65 | AZ7: ="G"&T8 -> G6 | BA7: =U8 -> 34.75 | BB7: =V8 -> 31 | BC7: =W8 -> 34.75 | BD7: =X8 -> 36.25
A8: 6 | B8: 5 | C8: 160 | D8: 20 | I8: =A8 -> 6 | J8: =MIN(100,IFERROR(VLOOKUP(B8,AA2:AB7,2,FALSE),IF(B8>=6,25,50))*$P$9) -> 40 | K8: =VLOOKUP(D8,AJ2:AK12,2,TRUE) -> 40 | L8: =VLOOKUP(C8,AG2:AH10,2,TRUE) -> 25 | M8: =($P$4*J8)+($P$5*K8)+($P$6*L8) -> 34.75 | O8: PriorityScore = | P8: W1×Capacity + W2×Fairness + W3×Urgency | Q8: =IF(D8>60,999,M8) -> 34.75 | R8: =RANK(Q8,$Q$3:$Q$8,0) -> 5 | T8: =A8 -> 6 | U8: =IF(D8>60,999,(INDEX(AT2:AW5,MATCH("Balanced",AT2:AT5,0),2)*J8)+(INDEX(AT2:AW5,MATCH("Balanced",AT2:AT5,0),3)*K8)+(INDEX(AT2:AW5,MATCH("Balanced",AT2:AT5,0),4)*L8)) -> 34.75 | V8: =IF(D8>60,999,(INDEX(AT2:AW5,MATCH("Revenue Focus",AT2:AT5,0),2)*J8)+(INDEX(AT2:AW5,MATCH("Revenue Focus",AT2:AT5,0),3)*K8)+(INDEX(AT2:AW5,MATCH("Revenue Focus",AT2:AT5,0),4)*L8)) -> 31 | W8: =IF(D8>60,999,(INDEX(AT2:AW5,MATCH("Efficiency Focus",AT2:AT5,0),2)*J8)+(INDEX(AT2:AW5,MATCH("Efficiency Focus",AT2:AT5,0),3)*K8)+(INDEX(AT2:AW5,MATCH("Efficiency Focus",AT2:AT5,0),4)*L8)) -> 34.75 | X8: =IF(D8>60,999,(INDEX(AT2:AW5,MATCH("Fairness First",AT2:AT5,0),2)*J8)+(INDEX(AT2:AW5,MATCH("Fairness First",AT2:AT5,0),3)*K8)+(INDEX(AT2:AW5,MATCH("Fairness First",AT2:AT5,0),4)*L8)) -> 36.25 | AD8: 180 | AE8: 15 | AG8: 150 | AH8: 25 | AJ8: 35 | AK8: 70 | AM8: 6 | AN8: 75 | AT8: Occupancy | AU8: Modifier
O9: Occ. Modifier | P9: =IF(P2="Low (<50%)",0.8,IF(P2="High (>80%)",1.2,1)) -> 1 | AD9: 9999 | AE9: 10 | AG9: 180 | AH9: 10 | AJ9: 40 | AK9: 80 | AM9: 7 | AN9: 82 | AT9: Low (<50%) | AU9: 0.8
A10: Hard Override Rules | E10: Model Weights Reference | J10: Score Formulas (Simplified) | T10: Rankings by Model | AG10: 9999 | AH10: 0 | AJ10: 50 | AK10: 90 | AM10: 8 | AN10: 90 | AT10: High (>80%) | AU10: 1.2
A11: Condition | B11: Override | C11: Logic | E11: Model | F11: W1 Cap | G11: W2 Fair | H11: W3 Urg | J11: Dimension | K11: Formula | T11: Group | U11: Balanced | V11: Revenue Focus | W11: Efficiency Focus | X11: Fairness First | AJ11: 60 | AK11: 95 | AM11: 9 | AN11: 95
A12: Wait Time > 60 min | B12: 999 | C12: MaxWait guard | E12: Balanced | F12: 0.35 | G12: 0.3 | H12: 0.35 | J12: Capacity | K12: VLOOKUP(PartySize) × OccMod | T12: =A3 -> 1 | U12: =RANK(U3,$U$3:$U$8,0) -> 2 | V12: =RANK(V3,$V$3:$V$8,0) -> 2 | W12: =RANK(W3,$W$3:$W$8,0) -> 2 | X12: =RANK(X3,$X$3:$X$8,0) -> 3 | AJ12: 9999 | AK12: 100
E13: Revenue Focus | F13: 0.2 | G13: 0.2 | H13: 0.6 | J13: Fairness | K13: VLOOKUP(WaitTime) | T13: =A4 -> 2 | U13: =RANK(U4,$U$3:$U$8,0) -> 4 | V13: =RANK(V4,$V$3:$V$8,0) -> 4 | W13: =RANK(W4,$W$3:$W$8,0) -> 4 | X13: =RANK(X4,$X$3:$X$8,0) -> 4
E14: Efficiency Focus | F14: 0.5 | G14: 0.15 | H14: 0.35 | J14: Urgency | K14: VLOOKUP(TTD) | T14: =A5 -> 3 | U14: =RANK(U5,$U$3:$U$8,0) -> 6 | V14: =RANK(V5,$V$3:$V$8,0) -> 6 | W14: =RANK(W5,$W$3:$W$8,0) -> 5 | X14: =RANK(X5,$X$3:$X$8,0) -> 6
E15: Fairness First | F15: 0.2 | G15: 0.55 | H15: 0.25 | T15: =A6 -> 4 | U15: =RANK(U6,$U$3:$U$8,0) -> 3 | V15: =RANK(V6,$V$3:$V$8,0) -> 3 | W15: =RANK(W6,$W$3:$W$8,0) -> 3 | X15: =RANK(X6,$X$3:$X$8,0) -> 2
T16: =A7 -> 5 | U16: =RANK(U7,$U$3:$U$8,0) -> 1 | V16: =RANK(V7,$V$3:$V$8,0) -> 1 | W16: =RANK(W7,$W$3:$W$8,0) -> 1 | X16: =RANK(X7,$X$3:$X$8,0) -> 1
T17: =A8 -> 6 | U17: =RANK(U8,$U$3:$U$8,0) -> 5 | V17: =RANK(V8,$V$3:$V$8,0) -> 5 | W17: =RANK(W8,$W$3:$W$8,0) -> 6 | X17: =RANK(X8,$X$3:$X$8,0) -> 5

Sheet Simulation v.3
A1: Front End | I1: Back End — Dimension Scores | O1: Selected Model | P1: Balanced | Q1: Result | T1: Scores by Model | AA1: PartySize | AB1: CapScore | AD1: EstStay_Max | AE1: StayScore | AG1: TTD_Max | AH1: TTDScore | AJ1: Wait_Max | AK1: WaitScore | AM1: Skips | AN1: SkipScore | AP1: AccessProgram | AQ1: Value_pp | AR1: RevScore | AT1: Model | AU1: W1_Revenue | AV1: W2_Capacity | AW1: W3_Fairness | AX1: W4_Urgency | AZ1: Group | BA1: Balanced | BB1: Revenue Focus | BC1: Efficiency Focus | BD1: Fairness First
A2: waitlist_id | B2: party_size | C2: time_to_departure | D2: access_program | E2: wait_time_min | F2: consecutive_skips | G2: est_stay_min | I2: waitlist_id | J2: Revenue Score | K2: Capacity Score | L2: Fairness Score | M2: Urgency Score | N2: PriModelScore | O2: Occupancy Level | P2: Medium | Q2: Final Score | R2: Rank | T2: Group | U2: Balanced | V2: Revenue Focus | W2: Efficiency Focus | X2: Fairness First | AA2: 1 | AB2: 100 | AD2: 20 | AE2: 100 | AG2: 15 | AH2: 100 | AJ2: 5 | AK2: 10 | AM2: 0 | AN2: 0 | AP2: Priority Pass | AQ2: 27 | AR2: 80 | AT2: Balanced | AU2: 0.25 | AV2: 0.25 | AW2: 0.3 | AX2: 0.2 | AZ2: ="G"&T3 -> G1 | BA2: =U3 -> 68.4 | BB2: =V3 -> 77.2 | BC2: =W3 -> 78.1 | BD2: =X3 -> 55
A3: 1 | B3: 1 | C3: 50 | D3: Priority Pass | E3: 15 | F3: 0 | G3: 20 | I3: =A3 -> 1 | J3: =IFERROR(VLOOKUP(D3,'Simulation v.3'!AP2:AR5,3,FALSE),50) -> 80 | K3: =MIN(100,((IFERROR(VLOOKUP(B3,'Simulation v.3'!AA2:AB7,2,FALSE),IF(B3>=6,25,50)))*0.4+(VLOOKUP(G3,'Simulation v.3'!AD2:AE9,2,TRUE))*0.6)*$P$9) -> 100 | L3: =(VLOOKUP(E3,'Simulation v.3'!AJ2:AK12,2,TRUE))*0.6+(IFERROR(VLOOKUP(F3,'Simulation v.3'!AM2:AN11,2,FALSE),IF(F3>=9,100,50)))*0.4 -> 18 | M3: =VLOOKUP(C3,'Simulation v.3'!AG2:AH10,2,TRUE) -> 90 | N3: =($P$4*J3)+($P$5*K3)+($P$6*L3)+($P$7*M3) -> 68.4 | Q3: =IF(E3>60,999,IF(F3>=10,998,N3)) -> 68.4 | R3: =RANK(Q3,$Q$3:$Q$8,0) -> 3 | T3: =A3 -> 1 | U3: =IF(E3>60,999,IF(F3>=10,998,(INDEX(AT2:AX5,MATCH("Balanced",AT2:AT5,0),2)*J3)+(INDEX(AT2:AX5,MATCH("Balanced",AT2:AT5,0),3)*K3)+(INDEX(AT2:AX5,MATCH("Balanced",AT2:AT5,0),4)*L3)+(INDEX(AT2:AX5,MATCH("Balanced",AT2:AT5,0),5)*M3))) -> 68.4 | V3: =IF(E3>60,999,IF(F3>=10,998,(INDEX(AT2:AX5,MATCH("Revenue Focus",AT2:AT5,0),2)*J3)+(INDEX(AT2:AX5,MATCH("Revenue Focus",AT2:AT5,0),3)*K3)+(INDEX(AT2:AX5,MATCH("Revenue Focus",AT2:AT5,0),4)*L3)+(INDEX(AT2:AX5,MATCH("Revenue Focus",AT2:AT5,0),5)*M3))) -> 77.2 | W3: =IF(E3>60,999,IF(F3>=10,998,(INDEX(AT2:AX5,MATCH("Efficiency Focus",AT2:AT5,0),2)*J3)+(INDEX(AT2:AX5,MATCH("Efficiency Focus",AT2:AT5,0),3)*K3)+(INDEX(AT2:AX5,MATCH("Efficiency Focus",AT2:AT5,0),4)*L3)+(INDEX(AT2:AX5,MATCH("Efficiency Focus",AT2:AT5,0),5)*M3))) -> 78.1 | X3: =IF(E3>60,999,IF(F3>=10,998,(INDEX(AT2:AX5,MATCH("Fairness First",AT2:AT5,0),2)*J3)+(INDEX(AT2:AX5,MATCH("Fairness First",AT2:AT5,0),3)*K3)+(INDEX(AT2:AX5,MATCH("Fairness First",AT2:AT5,0),4)*L3)+(INDEX(AT2:AX5,MATCH("Fairness First",AT2:AT5,0),5)*M3))) -> 55 | AA3: 2 | AB3: 85 | AD3: 40 | AE3: 85 | AG3: 30 | AH3: 95 | AJ3: 10 | AK3: 20 | AM3: 1 | AN3: 15 | AP3: LoungeKey | AQ3: 24 | AR3: 60 | AT3: Revenue Focus | AU3: 0.45 | AV3: 0.25 | AW3: 0.15 | AX3: 0.15 | AZ3: ="G"&T4 -> G2 | BA3: =U4 -> 46.85 | BB3: =V4 -> 56.8 | BC3: =W4 -> 50.95 | BD3: =X4 -> 35.4
A4: 2 | B4: 2 | C4: 120 | D4: Amex Platinum | E4: 10 | F4: 0 | G4: 90 | H4: → | I4: =A4 -> 2 | J4: =IFERROR(VLOOKUP(D4,'Simulation v.3'!AP2:AR5,3,FALSE),50) -> 70 | K4: =MIN(100,((IFERROR(VLOOKUP(B4,'Simulation v.3'!AA2:AB7,2,FALSE),IF(B4>=6,25,50)))*0.4+(VLOOKUP(G4,'Simulation v.3'!AD2:AE9,2,TRUE))*0.6)*$P$9) -> 67 | L4: =(VLOOKUP(E4,'Simulation v.3'!AJ2:AK12,2,TRUE))*0.6+(IFERROR(VLOOKUP(F4,'Simulation v.3'!AM2:AN11,2,FALSE),IF(F4>=9,100,50)))*0.4 -> 12 | M4: =VLOOKUP(C4,'Simulation v.3'!AG2:AH10,2,TRUE) -> 45 | N4: =($P$4*J4)+($P$5*K4)+($P$6*L4)+($P$7*M4) -> 46.85 | O4: W1 Revenue | P4: =VLOOKUP($P$1,AT2:AX5,2,FALSE) -> 0.25 | Q4: =IF(E4>60,999,IF(F4>=10,998,N4)) -> 46.85 | R4: =RANK(Q4,$Q$3:$Q$8,0) -> 4 | T4: =A4 -> 2 | U4: =IF(E4>60,999,IF(F4>=10,998,(INDEX(AT2:AX5,MATCH("Balanced",AT2:AT5,0),2)*J4)+(INDEX(AT2:AX5,MATCH("Balanced",AT2:AT5,0),3)*K4)+(INDEX(AT2:AX5,MATCH("Balanced",AT2:AT5,0),4)*L4)+(INDEX(AT2:AX5,MATCH("Balanced",AT2:AT5,0),5)*M4))) -> 46.85 | V4: =IF(E4>60,999,IF(F4>=10,998,(INDEX(AT2:AX5,MATCH("Revenue Focus",AT2:AT5,0),2)*J4)+(INDEX(AT2:AX5,MATCH("Revenue Focus",AT2:AT5,0),3)*K4)+(INDEX(AT2:AX5,MATCH("Revenue Focus",AT2:AT5,0),4)*L4)+(INDEX(AT2:AX5,MATCH("Revenue Focus",AT2:AT5,0),5)*M4))) -> 56.8 | W4: =IF(E4>60,999,IF(F4>=10,998,(INDEX(AT2:AX5,MATCH("Efficiency Focus",AT2:AT5,0),2)*J4)+(INDEX(AT2:AX5,MATCH("Efficiency Focus",AT2:AT5,0),3)*K4)+(INDEX(AT2:AX5,MATCH("Efficiency Focus",AT2:AT5,0),4)*L4)+(INDEX(AT2:AX5,MATCH("Efficiency Focus",AT2:AT5,0),5)*M4))) -> 50.95 | X4: =IF(E4>60,999,IF(F4>=10,998,(INDEX(AT2:AX5,MATCH("Fairness First",AT2:AT5,0),2)*J4)+(INDEX(AT2:AX5,MATCH("Fairness First",AT2:AT5,0),3)*K4)+(INDEX(AT2:AX5,MATCH("Fairness First",AT2:AT5,0),4)*L4)+(INDEX(AT2:AX5,MATCH("Fairness First",AT2:AT5,0),5)*M4))) -> 35.4 | AA4: 3 | AB4: 70 | AD4: 60 | AE4: 70 | AG4: 45 | AH4: 90 | AJ4: 15 | AK4: 30 | AM4: 2 | AN4: 30 | AP4: Amex Platinum | AQ4: 25 | AR4: 70 | AT4: Efficiency Focus | AU4: 0.15 | AV4: 0.4 | AW4: 0.2 | AX4: 0.25 | AZ4: ="G"&T5 -> G3 | BA4: =U5 -> 29.55 | BB4: =V5 -> 40.15 | BC4: =W5 -> 29.9 | BD4: =X5 -> 19.6
A5: 3 | B5: 3 | C5: 180 | D5: LoungeKey | E5: 5 | F5: 0 | G5: 150 | I5: =A5 -> 3 | J5: =IFERROR(VLOOKUP(D5,'Simulation v.3'!AP2:AR5,3,FALSE),50) -> 60 | K5: =MIN(100,((IFERROR(VLOOKUP(B5,'Simulation v.3'!AA2:AB7,2,FALSE),IF(B5>=6,25,50)))*0.4+(VLOOKUP(G5,'Simulation v.3'!AD2:AE9,2,TRUE))*0.6)*$P$9) -> 43 | L5: =(VLOOKUP(E5,'Simulation v.3'!AJ2:AK12,2,TRUE))*0.6+(IFERROR(VLOOKUP(F5,'Simulation v.3'!AM2:AN11,2,FALSE),IF(F5>=9,100,50)))*0.4 -> 6 | M5: =VLOOKUP(C5,'Simulation v.3'!AG2:AH10,2,TRUE) -> 10 | N5: =($P$4*J5)+($P$5*K5)+($P$6*L5)+($P$7*M5) -> 29.55 | O5: W2 Capacity | P5: =VLOOKUP($P$1,AT2:AX5,3,FALSE) -> 0.25 | Q5: =IF(E5>60,999,IF(F5>=10,998,N5)) -> 29.55 | R5: =RANK(Q5,$Q$3:$Q$8,0) -> 6 | T5: =A5 -> 3 | U5: =IF(E5>60,999,IF(F5>=10,998,(INDEX(AT2:AX5,MATCH("Balanced",AT2:AT5,0),2)*J5)+(INDEX(AT2:AX5,MATCH("Balanced",AT2:AT5,0),3)*K5)+(INDEX(AT2:AX5,MATCH("Balanced",AT2:AT5,0),4)*L5)+(INDEX(AT2:AX5,MATCH("Balanced",AT2:AT5,0),5)*M5))) -> 29.55 | V5: =IF(E5>60,999,IF(F5>=10,998,(INDEX(AT2:AX5,MATCH("Revenue Focus",AT2:AT5,0),2)*J5)+(INDEX(AT2:AX5,MATCH("Revenue Focus",AT2:AT5,0),3)*K5)+(INDEX(AT2:AX5,MATCH("Revenue Focus",AT2:AT5,0),4)*L5)+(INDEX(AT2:AX5,MATCH("Revenue Focus",AT2:AT5,0),5)*M5))) -> 40.15 | W5: =IF(E5>60,999,IF(F5>=10,998,(INDEX(AT2:AX5,MATCH("Efficiency Focus",AT2:AT5,0),2)*J5)+(INDEX(AT2:AX5,MATCH("Efficiency Focus",AT2:AT5,0),3)*K5)+(INDEX(AT2:AX5,MATCH("Efficiency Focus",AT2:AT5,0),4)*L5)+(INDEX(AT2:AX5,MATCH("Efficiency Focus",AT2:AT5,0),5)*M5))) -> 29.9 | X5: =IF(E5>60,999,IF(F5>=10,998,(INDEX(AT2:AX5,MATCH("Fairness First",AT2:AT5,0),2)*J5)+(INDEX(AT2:AX5,MATCH("Fairness First",AT2:AT5,0),3)*K5)+(INDEX(AT2:AX5,MATCH("Fairness First",AT2:AT5,0),4)*L5)+(INDEX(AT2:AX5,MATCH("Fairness First",AT2:AT5,0),5)*M5))) -> 19.6 | AA5: 4 | AB5: 55 | AD5: 90 | AE5: 55 | AG5: 60 | AH5: 80 | AJ5: 20 | AK5: 40 | AM5: 3 | AN5: 45 | AP5: Day Pass (walk-in) | AQ5: 35 | AR5: 100 | AT5: Fairness First | AU5: 0.1 | AV5: 0.2 | AW5: 0.5 | AX5: 0.2 | AZ5: ="G"&T6 -> G4 | BA5: =U6 -> 76.2 | BB5: =V6 -> 82.6 | BC5: =W6 -> 73.4 | BD5: =X6 -> 70.8
A6: 4 | B6: 4 | C6: 89 | D6: Day Pass (walk-in) | E6: 35 | F6: 4 | G6: 60 | I6: =A6 -> 4 | J6: =IFERROR(VLOOKUP(D6,'Simulation v.3'!AP2:AR5,3,FALSE),50) -> 100 | K6: =MIN(100,((IFERROR(VLOOKUP(B6,'Simulation v.3'!AA2:AB7,2,FALSE),IF(B6>=6,25,50)))*0.4+(VLOOKUP(G6,'Simulation v.3'!AD2:AE9,2,TRUE))*0.6)*$P$9) -> 64 | L6: =(VLOOKUP(E6,'Simulation v.3'!AJ2:AK12,2,TRUE))*0.6+(IFERROR(VLOOKUP(F6,'Simulation v.3'!AM2:AN11,2,FALSE),IF(F6>=9,100,50)))*0.4 -> 64 | M6: =VLOOKUP(C6,'Simulation v.3'!AG2:AH10,2,TRUE) -> 80 | N6: =($P$4*J6)+($P$5*K6)+($P$6*L6)+($P$7*M6) -> 76.2 | O6: W3 Fairness | P6: =VLOOKUP($P$1,AT2:AX5,4,FALSE) -> 0.3 | Q6: =IF(E6>60,999,IF(F6>=10,998,N6)) -> 76.2 | R6: =RANK(Q6,$Q$3:$Q$8,0) -> 2 | T6: =A6 -> 4 | U6: =IF(E6>60,999,IF(F6>=10,998,(INDEX(AT2:AX5,MATCH("Balanced",AT2:AT5,0),2)*J6)+(INDEX(AT2:AX5,MATCH("Balanced",AT2:AT5,0),3)*K6)+(INDEX(AT2:AX5,MATCH("Balanced",AT2:AT5,0),4)*L6)+(INDEX(AT2:AX5,MATCH("Balanced",AT2:AT5,0),5)*M6))) -> 76.2 | V6: =IF(E6>60,999,IF(F6>=10,998,(INDEX(AT2:AX5,MATCH("Revenue Focus",AT2:AT5,0),2)*J6)+(INDEX(AT2:AX5,MATCH("Revenue Focus",AT2:AT5,0),3)*K6)+(INDEX(AT2:AX5,MATCH("Revenue Focus",AT2:AT5,0),4)*L6)+(INDEX(AT2:AX5,MATCH("Revenue Focus",AT2:AT5,0),5)*M6))) -> 82.6 | W6: =IF(E6>60,999,IF(F6>=10,998,(INDEX(AT2:AX5,MATCH("Efficiency Focus",AT2:AT5,0),2)*J6)+(INDEX(AT2:AX5,MATCH("Efficiency Focus",AT2:AT5,0),3)*K6)+(INDEX(AT2:AX5,MATCH("Efficiency Focus",AT2:AT5,0),4)*L6)+(INDEX(AT2:AX5,MATCH("Efficiency Focus",AT2:AT5,0),5)*M6))) -> 73.4 | X6: =IF(E6>60,999,IF(F6>=10,998,(INDEX(AT2:AX5,MATCH("Fairness First",AT2:AT5,0),2)*J6)+(INDEX(AT2:AX5,MATCH("Fairness First",AT2:AT5,0),3)*K6)+(INDEX(AT2:AX5,MATCH("Fairness First",AT2:AT5,0),4)*L6)+(INDEX(AT2:AX5,MATCH("Fairness First",AT2:AT5,0),5)*M6))) -> 70.8 | AA6: 5 | AB6: 40 | AD6: 120 | AE6: 40 | AG6: 90 | AH6: 65 | AJ6: 25 | AK6: 50 | AM6: 4 | AN6: 55 | AZ6: ="G"&T7 -> G5 | BA6: =U7 -> 85.7 | BB6: =V7 -> 85.6 | BC6: =W7 -> 89.4 | BD6: =X7 -> 83.8
A7: 5 | B7: 2 | C7: 25 | D7: Priority Pass | E7: 40 | F7: 5 | G7: 25 | I7: =A7 -> 5 | J7: =IFERROR(VLOOKUP(D7,'Simulation v.3'!AP2:AR5,3,FALSE),50) -> 80 | K7: =MIN(100,((IFERROR(VLOOKUP(B7,'Simulation v.3'!AA2:AB7,2,FALSE),IF(B7>=6,25,50)))*0.4+(VLOOKUP(G7,'Simulation v.3'!AD2:AE9,2,TRUE))*0.6)*$P$9) -> 94 | L7: =(VLOOKUP(E7,'Simulation v.3'!AJ2:AK12,2,TRUE))*0.6+(IFERROR(VLOOKUP(F7,'Simulation v.3'!AM2:AN11,2,FALSE),IF(F7>=9,100,50)))*0.4 -> 74 | M7: =VLOOKUP(C7,'Simulation v.3'!AG2:AH10,2,TRUE) -> 100 | N7: =($P$4*J7)+($P$5*K7)+($P$6*L7)+($P$7*M7) -> 85.7 | O7: W4 Urgency | P7: =VLOOKUP($P$1,AT2:AX5,5,FALSE) -> 0.2 | Q7: =IF(E7>60,999,IF(F7>=10,998,N7)) -> 85.7 | R7: =RANK(Q7,$Q$3:$Q$8,0) -> 1 | T7: =A7 -> 5 | U7: =IF(E7>60,999,IF(F7>=10,998,(INDEX(AT2:AX5,MATCH("Balanced",AT2:AT5,0),2)*J7)+(INDEX(AT2:AX5,MATCH("Balanced",AT2:AT5,0),3)*K7)+(INDEX(AT2:AX5,MATCH("Balanced",AT2:AT5,0),4)*L7)+(INDEX(AT2:AX5,MATCH("Balanced",AT2:AT5,0),5)*M7))) -> 85.7 | V7: =IF(E7>60,999,IF(F7>=10,998,(INDEX(AT2:AX5,MATCH("Revenue Focus",AT2:AT5,0),2)*J7)+(INDEX(AT2:AX5,MATCH("Revenue Focus",AT2:AT5,0),3)*K7)+(INDEX(AT2:AX5,MATCH("Revenue Focus",AT2:AT5,0),4)*L7)+(INDEX(AT2:AX5,MATCH("Revenue Focus",AT2:AT5,0),5)*M7))) -> 85.6 | W7: =IF(E7>60,999,IF(F7>=10,998,(INDEX(AT2:AX5,MATCH("Efficiency Focus",AT2:AT5,0),2)*J7)+(INDEX(AT2:AX5,MATCH("Efficiency Focus",AT2:AT5,0),3)*K7)+(INDEX(AT2:AX5,MATCH("Efficiency Focus",AT2:AT5,0),4)*L7)+(INDEX(AT2:AX5,MATCH("Efficiency Focus",AT2:AT5,0),5)*M7))) -> 89.4 | X7: =IF(E7>60,999,IF(F7>=10,998,(INDEX(AT2:AX5,MATCH("Fairness First",AT2:AT5,0),2)*J7)+(INDEX(AT2:AX5,MATCH("Fairness First",AT2:AT5,0),3)*K7)+(INDEX(AT2:AX5,MATCH("Fairness First",AT2:AT5,0),4)*L7)+(INDEX(AT2:AX5,MATCH("Fairness First",AT2:AT5,0),5)*M7))) -> 83.8 | AA7: 6 | AB7: 25 | AD7: 150 | AE7: 25 | AG7: 120 | AH7: 45 | AJ7: 30 | AK7: 60 | AM7: 5 | AN7: 65 | AZ7: ="G"&T8 -> G6 | BA7: =U8 -> 40.8 | BB7: =V8 -> 46.15 | BC7: =W8 -> 38.45 | BD7: =X8 -> 37
A8: 6 | B8: 5 | C8: 160 | D8: LoungeKey | E8: 20 | F8: 2 | G8: 120 | I8: =A8 -> 6 | J8: =IFERROR(VLOOKUP(D8,'Simulation v.3'!AP2:AR5,3,FALSE),50) -> 60 | K8: =MIN(100,((IFERROR(VLOOKUP(B8,'Simulation v.3'!AA2:AB7,2,FALSE),IF(B8>=6,25,50)))*0.4+(VLOOKUP(G8,'Simulation v.3'!AD2:AE9,2,TRUE))*0.6)*$P$9) -> 40 | L8: =(VLOOKUP(E8,'Simulation v.3'!AJ2:AK12,2,TRUE))*0.6+(IFERROR(VLOOKUP(F8,'Simulation v.3'!AM2:AN11,2,FALSE),IF(F8>=9,100,50)))*0.4 -> 36 | M8: =VLOOKUP(C8,'Simulation v.3'!AG2:AH10,2,TRUE) -> 25 | N8: =($P$4*J8)+($P$5*K8)+($P$6*L8)+($P$7*M8) -> 40.8 | Q8: =IF(E8>60,999,IF(F8>=10,998,N8)) -> 40.8 | R8: =RANK(Q8,$Q$3:$Q$8,0) -> 5 | T8: =A8 -> 6 | U8: =IF(E8>60,999,IF(F8>=10,998,(INDEX(AT2:AX5,MATCH("Balanced",AT2:AT5,0),2)*J8)+(INDEX(AT2:AX5,MATCH("Balanced",AT2:AT5,0),3)*K8)+(INDEX(AT2:AX5,MATCH("Balanced",AT2:AT5,0),4)*L8)+(INDEX(AT2:AX5,MATCH("Balanced",AT2:AT5,0),5)*M8))) -> 40.8 | V8: =IF(E8>60,999,IF(F8>=10,998,(INDEX(AT2:AX5,MATCH("Revenue Focus",AT2:AT5,0),2)*J8)+(INDEX(AT2:AX5,MATCH("Revenue Focus",AT2:AT5,0),3)*K8)+(INDEX(AT2:AX5,MATCH("Revenue Focus",AT2:AT5,0),4)*L8)+(INDEX(AT2:AX5,MATCH("Revenue Focus",AT2:AT5,0),5)*M8))) -> 46.15 | W8: =IF(E8>60,999,IF(F8>=10,998,(INDEX(AT2:AX5,MATCH("Efficiency Focus",AT2:AT5,0),2)*J8)+(INDEX(AT2:AX5,MATCH("Efficiency Focus",AT2:AT5,0),3)*K8)+(INDEX(AT2:AX5,MATCH("Efficiency Focus",AT2:AT5,0),4)*L8)+(INDEX(AT2:AX5,MATCH("Efficiency Focus",AT2:AT5,0),5)*M8))) -> 38.45 | X8: =IF(E8>60,999,IF(F8>=10,998,(INDEX(AT2:AX5,MATCH("Fairness First",AT2:AT5,0),2)*J8)+(INDEX(AT2:AX5,MATCH("Fairness First",AT2:AT5,0),3)*K8)+(INDEX(AT2:AX5,MATCH("Fairness First",AT2:AT5,0),4)*L8)+(INDEX(AT2:AX5,MATCH("Fairness First",AT2:AT5,0),5)*M8))) -> 37 | AD8: 180 | AE8: 15 | AG8: 150 | AH8: 25 | AJ8: 35 | AK8: 70 | AM8: 6 | AN8: 75 | AT8: Occupancy | AU8: Modifier
O9: Occ. Modifier | P9: =IF(P2="Low (<50%)",0.8,IF(P2="High (>80%)",1.2,1)) -> 1 | AD9: 9999 | AE9: 10 | AG9: 180 | AH9: 10 | AJ9: 40 | AK9: 80 | AM9: 7 | AN9: 82 | AT9: Low (<50%) | AU9: 0.8
A10: Hard Override Rules | E10: Model Weights Reference | K10: Score Formulas | T10: Rankings by Model | AG10: 9999 | AH10: 0 | AJ10: 50 | AK10: 90 | AM10: 8 | AN10: 90 | AT10: High (>80%) | AU10: 1.2
A11: Condition | B11: Override | C11: Logic | E11: Model | F11: W1 Rev | G11: W2 Cap | H11: W3 Fair | I11: W4 Urg | K11: Revenue | L11: VLOOKUP(AccessProgram → RevScore) | T11: Group | U11: Balanced | V11: Revenue Focus | W11: Efficiency Focus | X11: Fairness First | AJ11: 60 | AK11: 95 | AM11: 9 | AN11: 95
A12: Wait Time > 60 min | B12: 999 | C12: MaxWait guard | E12: Balanced | F12: 0.25 | G12: 0.25 | H12: 0.3 | I12: 0.2 | K12: Capacity | L12: (PartySize×0.4 + EstStay×0.6) × OccMod | T12: =A3 -> 1 | U12: =RANK(U3,$U$3:$U$8,0) -> 3 | V12: =RANK(V3,$V$3:$V$8,0) -> 3 | W12: =RANK(W3,$W$3:$W$8,0) -> 2 | X12: =RANK(X3,$X$3:$X$8,0) -> 3 | AJ12: 9999 | AK12: 100
A13: Skips ≥ 10 | B13: 998 | C13: Starvation guard | E13: Revenue Focus | F13: 0.45 | G13: 0.25 | H13: 0.15 | I13: 0.15 | K13: Fairness | L13: (WaitScore×0.6) + (SkipScore×0.4) | T13: =A4 -> 2 | U13: =RANK(U4,$U$3:$U$8,0) -> 4 | V13: =RANK(V4,$V$3:$V$8,0) -> 4 | W13: =RANK(W4,$W$3:$W$8,0) -> 4 | X13: =RANK(X4,$X$3:$X$8,0) -> 5
E14: Efficiency Focus | F14: 0.15 | G14: 0.4 | H14: 0.2 | I14: 0.25 | K14: Urgency | L14: VLOOKUP(TTD → TTDScore) | T14: =A5 -> 3 | U14: =RANK(U5,$U$3:$U$8,0) -> 6 | V14: =RANK(V5,$V$3:$V$8,0) -> 6 | W14: =RANK(W5,$W$3:$W$8,0) -> 6 | X14: =RANK(X5,$X$3:$X$8,0) -> 6
E15: Fairness First | F15: 0.1 | G15: 0.2 | H15: 0.5 | I15: 0.2 | T15: =A6 -> 4 | U15: =RANK(U6,$U$3:$U$8,0) -> 2 | V15: =RANK(V6,$V$3:$V$8,0) -> 2 | W15: =RANK(W6,$W$3:$W$8,0) -> 3 | X15: =RANK(X6,$X$3:$X$8,0) -> 2
T16: =A7 -> 5 | U16: =RANK(U7,$U$3:$U$8,0) -> 1 | V16: =RANK(V7,$V$3:$V$8,0) -> 1 | W16: =RANK(W7,$W$3:$W$8,0) -> 1 | X16: =RANK(X7,$X$3:$X$8,0) -> 1
T17: =A8 -> 6 | U17: =RANK(U8,$U$3:$U$8,0) -> 5 | V17: =RANK(V8,$V$3:$V$8,0) -> 5 | W17: =RANK(W8,$W$3:$W$8,0) -> 5 | X17: =RANK(X8,$X$3:$X$8,0) -> 4

Sheet Simulation
A1: Front End | I1: Back End | O1: Selected Model | P1: Urgency
A2: waitlist_id | B2: party_size | C2: time_to_departure_min | D2: access_program_type | I2: waitlist_id | J2: party_size | K2: time_to_departure_min | L2: access_program_type | M2: priority_score
A3: 1 | B3: 6 | C3: 12 | D3: Priority Pass | I3: 1 | J3: 40 | K3: 100 | L3: 100 | M3: =(J3*$P$3)+(K3*$P$4)+(L3*$P$5) -> 88 | O3: Party size | P3: 0.2
A4: 2 | B4: 2 | C4: 12 | D4: LoungeKey | I4: 2 | J4: 85 | K4: 100 | L4: 85 | M4: =(J4*$P$3)+(K4*$P$4)+(L4*$P$5) -> 94.75 | O4: Time to departure | P4: 0.65
A5: 3 | B5: 1 | C5: 45 | D5: Amex Platinum | I5: 3 | J5: 100 | K5: 75 | L5: 75 | M5: =(J5*$P$3)+(K5*$P$4)+(L5*$P$5) -> 80 | O5: Access program type | P5: 0.15
A6: 4 | B6: 9 | C6: 89 | D6: Day Pass (walk-in) | I6: 4 | J6: 40 | K6: 55 | L6: 55 | M6: =(J6*$P$3)+(K6*$P$4)+(L6*$P$5) -> 52
A7: 5 | B7: 3 | C7: 160 | D7: LoungeKey | I7: 5 | J7: 70 | K7: 35 | L7: 85 | M7: =(J7*$P$3)+(K7*$P$4)+(L7*$P$5) -> 49.5
A8: 6 | B8: 4 | C8: 185 | D8: Amex Platinum | I8: 6 | J8: 55 | K8: 20 | L8: 75 | M8: =(J8*$P$3)+(K8*$P$4)+(L8*$P$5) -> 35.25 | O8: PriorityScore = ModelWeight (PartySizeScore)+ ModelWeight (TTDScore) + ModelWeight (AccessProgramScore)
A15: Model Weigths
A17: Revenue
A18: Party size | B18: 0.1 | D18: PriorityScore = 0.20(PartySizeScore)+0.35(TTDScore)+0.25(AccessProgramScore)
A19: Time to departure | B19: 0.7
A20: Access program type | B20: 0.2
B21: =SUM(B18:B20) -> 1
A23: Urgency
A24: Party size | B24: 0.2
A25: Time to departure | B25: 0.65
A26: Access program type | B26: 0.15
B27: =SUM(B24:B26) -> 1

Sheet Weights
A1: OPTIMIZATION MODES - Weight Configuration
A2: Admin configures per lounge. Staff sees active mode as badge. All weights are admin-configurable.
A4: Model | B4: W1 Revenue | C4: W2 Capacity | D4: W3 Fairness | E4: W4 Urgency | F4: When to Use
A5: Balanced (default) | B5: 0.25 | C5: 0.25 | D5: 0.3 | E5: 0.2 | F5: General purpose. Fairness slightly dominant. Safe default.
A6: Revenue Focus | B6: 0.45 | C6: 0.25 | D6: 0.15 | E6: 0.15 | F6: AD-operated lounges. Commercial yield KPI. Revenue primary signal.
A7: Efficiency Focus | B7: 0.15 | C7: 0.4 | D7: 0.2 | E7: 0.25 | F7: Peak hours, long queues. Capacity dominant. Cycles short-stay passengers.
A8: Fairness First | B8: 0.1 | C8: 0.2 | D8: 0.5 | E8: 0.2 | F8: After complaints. Wait time overwhelming factor.
A10: Hard constraint: W3 (Fairness) must never drop below 0.10 in any mode or custom configuration.
A12: Score Formula
A13: PriModelScore = (W1 x RevenueScore) + (W2 x CapacityScore) + (W3 x FairnessScore) + (W4 x UrgencyScore)
A14: All sub-scores normalized to 0-100 range. Final PriModelScore range: 0-100.
A15: (Suggestion) Top 3 entries by PriModelScore are presented to staff as suggestion cards or Show all the ranking and its potisions.
A21: Party Size | D21: Time to departure (minutes) | G21: Access program type
A22: Party size | B22: Party size score | D22: Time to departure | E22: TTD score | G22: Access program type | H22: Access program score
A23: 1 | B23: 100 | D23: 0–15 min | E23: 100 | G23: Priority Pass | H23: 100
A24: 2 | B24: 85 | D24: 16–30 min | E24: 90 | G24: LoungeKey | H24: 85
A25: 3 | B25: 70 | D25: 31–60 min | E25: 75 | G25: Amex Platinum | H25: 75
A26: 4 | B26: 55 | D26: 61–120 min | E26: 55 | G26: Day Pass (walk-in) | H26: 55
A27: 5+ | B27: 40 | D27: 121–180 min | E27: 35
D28: >180 min | E28: 20

Sheet Dimensions v.2
A1: THE FOUR DIMENSIONS OF PRIORITIZATION
A3: PriModel evaluates each waitlist entry across four dimensions. Each captures a fundamentally different aspect of the admission decision.
A5: Dimension | B5: Color | C5: What it answers | D5: Core metric | E5: Why it matters
A6: Revenue | B6: Red | C6: How much is this group worth commercially? | D6: Value per person ($) via lookup table | E6: Day Pass at $35/pp vs LoungeKey at $24/pp. Over a full day, revenue-aware ordering adds thousands in incremental yield.
A7: Capacity | B7: Blue | C7: How much space and time will this group consume? | D7: Party size score + Estimated stay score | E7: Solo staying 20 min = 100 on Capacity. Group of 3 staying 2.5h = 37. That gap determines 1 admission vs 4 in the same window.
A8: Fairness | B8: Green | C8: How long has this group waited, and how many times were they skipped? | D8: Wait time score + Consecutive skips score | E8: A passenger at 40 min with 5 skips scores 74 on Fairness. One at 5 min with 0 skips scores 6. Without tracking, high-value newcomers push others down indefinitely.
A9: Urgency | B9: Amber | C9: How close is the flight to departure? | D9: Time to departure score (no taper) | E9: 15 min to departure = 100. 3 hours = 0. Short visits are optimal: passenger uses entitlement, lounge collects fee, seat frees fast.
A12: How dimensions combine
A13: Each dimension produces a sub-score on a 0-100 scale via parametrized lookup tables.
A14: The four sub-scores are combined with configurable weights into a single PriModelScore (0-100):
A16: PriModelScore = (W1 x RevenueScore) + (W2 x CapacityScore) + (W3 x FairnessScore) + (W4 x UrgencyScore)
A17: Top 3 entries by PriModelScore are presented to staff as suggestion cards.
A19: The system suggests, the staff decides.
A21: Key design principles
A22: Principle | B22: Description
A23: Advisory only | B23: PriModel suggests, staff decides. No automated admission.
A24: Lounge-scoped | B24: Every parameter is configurable per lounge.
A25: Graceful degradation | B25: Missing data produces neutral scores (50), never penalties.
A26: Fairness floor | B26: No configuration can reduce fairness weight below 0.10.
A27: Passenger-invisible | B27: Passengers never see scores, dimensions, or prioritization logic.
A28: Full parametrization | B28: Every lookup table value, boundary, and weight is admin-configurable without code changes.
A29: Short visits are optimal | B29: A 10-minute visit collects the fee, frees the seat, and maximizes throughput. No taper penalty.

Sheet Decided varibles
A1: SYSTEM VARIABLES
A3: Every input PriModel uses, mapped to its dimension, source, type, availability, and which lookup table it feeds.
A5: # | B5: Variable | C5: Type | E5: Dimension(s) | F5: Feeds Lookup Table | G5: Source | H5: Available? | I5: Notes
A6: 1 | B6: Wait time (min elapsed) | C6: Derived | E6: Fairness | F6: LT-Fairness: Wait Time | G6: current_time minus join_timestamp | H6: Always | I6: Primary fairness signal. Updates every refresh cycle.
A7: 2 | B7: Party size | C7: Raw | E7: Revenue, Capacity | F7: LT-Capacity: Party Size | G7: Enrollment field (passenger or staff) | H7: Always | I7: Mandatory field. Impacts capacity consumption and revenue multiplier.
A8: 3 | B8: Flight number | C8: Raw | E8: Urgency, Capacity | F8: (resolves to #4, #5, #6, #7) | G8: Enrollment field (mandatory) | H8: Always | I8: Mandatory. Single input that unlocks departure time, status, and estimated stay.
A9: 4 | B9: Flight departure time | C9: Derived | E9: Urgency, Capacity | F9: (feeds #5 and #7) | G9: Flight API (from flight number) | H9: Always | I9: Auto-populated. Real-time updates if airline reschedules.
A10: 5 | B10: Time to departure (min) | C10: Derived | E10: Urgency | F10: LT-Urgency: TTD Score | G10: departure_time minus current_time | H10: Always | I10: Core urgency signal. Closer = higher score. No taper.
A11: 6 | B11: Flight status | C11: Derived | E11: Urgency | F11: LT-Urgency: Flight Status Modifier | G11: Flight API real-time | H11: Always | I11: On Time, Delayed, Boarding, Departed, Not Found.
A12: 7 | B12: Estimated stay (min) | C12: Derived | E12: Capacity | F12: LT-Capacity: Est Stay | G12: min(max_stay_limit, TTD minus boarding_buffer) | H12: Always | I12: Derived from flight data. Fallback: default_stay_estimate (120 min).
A13: 8 | B13: Consecutive skips | C13: Derived | E13: Fairness | F13: LT-Fairness: Skips Score | G13: Increments on each admission event while entry waits | H13: Always | I13: Starvation signal. Skipped 8 times != skipped once.
A14: 9 | B14: Current occupancy (%) | C14: Derived | D14: Dynamic | E14: Capacity | F14: Occupancy Pressure Modifier | G14: LMS headcount vs max capacity | H14: Yes | I14: Drives modifier: Low (<50%) x0.8, Med x1.0, High (>80%) x1.2.
A15: 10 | B15: Available seats estimate | C15: Derived | E15: Capacity | F15: (context for staff cards) | G15: max_capacity minus headcount | H15: Yes | I15: Group of 4 with 2 seats != group of 4 with 20 seats.
A16: 11 | B16: Pre-bookings (next N min) | C16: Raw | E16: Capacity | F16: (adjusts effective available seats) | G16: Pre-booking system (native LMS) | H16: Yes | I16: Native LMS data. Reduces effective available seats for capacity calc.
A17: 12 | B17: Access program | C17: Raw | E17: Revenue | F17: LT-Revenue: Value/pp Score | G17: Passenger-declared or staff-added | H17: Frequently missing | I17: PP, LK, Amex, Day Pass, etc. Maps to benefit card fee. Primary revenue gap at launch.
A18: 13 | B18: Value per person ($/pp) | C18: Derived | E18: Revenue | F18: LT-Revenue: Value/pp Score | G18: Revenue waterfall: deal > benefit card > default > neutral 50 | H18: Hard to get | I18: Depends on access program (#12) or membership ID (#15).
A19: 14 | B19: Total group value | C19: Derived | E19: Revenue | F19: (context for staff cards) | G19: value/pp x party_size | H19: Hard to get | I19: Displayed on suggestion cards. Not a separate scoring input.
A20: 15 | B20: Membership ID | C20: Raw | E20: Revenue (key) | F20: (unlocks deal pipeline for #13) | G20: Self-service, DMC scan, or app auto-ID | H20: Phase 3 | I20: Three acquisition paths. PPF app timeline: late 2026.
A21: 16 | B21: Day-of-week pattern | C21: Derived | E21: Capacity (context) | F21: (future ETA enhancement) | G21: Historical analytics | H21: Phase 3+ | I21: Friday afternoon throughput differs from Tuesday morning.
A24: Visit Fee Reference
A25: Program | B25: Value/pp | C25: Rationale
A26: Day Pass (walk-in) | B26: $35 | C26: No issuer deal. Lounge retains full margin.
A27: Priority Pass | B27: $27 | C27: Standard issuer deal rate.
A28: Amex Platinum | B28: $25 | C28: Issuer-negotiated rate.
A29: LoungeKey | B29: $24 | C29: Standard issuer deal rate.
A31: Color legend (availability)
A32: Green | B32: Always available at launch
A33: Teal | B33: Available with standard LMS
A34: Amber | B34: Frequently missing / hard to get
A35: Purple | B35: Requires integration or Phase 3+
A37: Type legend
A38: Raw | B38: Captured directly from passenger, staff, or system. No calculation.
A39: Derived | B39: Calculated from other variables. Automatic, no manual input needed.

Sheet Normalization
A1: PARAMETRIZED NORMALIZATION
A2: How raw variables become scores
A4: The problem
A5: Raw variables have different units and scales. Party size is 1-6+. Wait time is 0-60+ minutes. Time to departure is 0-180+ minutes. Value per person is $0-$35+. These cannot be compared or weighted directly.
A7: The solution: lookup tables
A8: Each raw variable passes through a lookup table that converts it to a score on a 0-100 scale. The lookup tables are fixed per lounge configuration. They do not change when the queue composition changes.
A10: Why parametrized (not relative)
A11: Aspect | B11: Parametrized (lookup tables) | C11: Relative (divide by queue max)
A12: Stability | B12: party_size=1 always scores 100 on Capacity | C12: Score changes every time someone joins or leaves the queue
A13: Predictability | B13: Staff learns: solo with near departure = high score | C13: Same solo can rank #1 or #3 depending on who else is in line
A14: Testability | B14: QA verifies: input X always produces output Y | C14: Test cases depend on full queue state
A15: Debuggability | B15: Trace back to fixed lookup value | C15: Trace back to dynamic normalization across N entries
A16: Internal approval | B16: Visible tables that anyone can review | C16: Formula that requires simulation to understand
A19: Example: party_size = 2
A20: Approach | B20: Queue has [1, 2, 3] | C20: Queue has [2, 2, 5] | D20: Queue has [2]
A21: Parametrized | B21: Score = 85 (always) | C21: Score = 85 (always) | D21: Score = 85 (always)
A22: Relative | B22: Score = 0.67 (2/3 = mid) | C22: Score = 0.60 (2/5 = low-mid) | D22: Score = 1.00 (2/2 = max)
A24: With parametrized normalization, the score is always 85. With relative, it fluctuates between 0.60 and 1.00 depending on who else is in the queue. Staff cannot build intuition on a moving target.
A26: Future evolution
A27: Parametrized normalization is the Phase 2 starting point. In Phase 3+, the model can evolve to hybrid normalization (parametrized base + relative adjustment within each dimension) or fully relative scoring as the team gains confidence and data coverage improves.

Sheet Data Flow v.2
A1: DATA FLOW: FRONT-END TO SCORE
A2: How raw inputs become a PriModelScore
A4: Stage 1: Front-End Capture
A5: Field | B5: Who provides it | C5: Required? | D5: Example
A6: waitlistID | B6: System-generated | C6: Auto | D6: WL-20250323-001
A7: party_size | B7: Passenger or staff | C7: Mandatory | D7: 2
A8: flight_number | B8: Passenger or staff | C8: Mandatory | D8: LA 635
A9: access_program | B9: Passenger or staff | C9: Optional | D9: Priority Pass (frequently missing)
A12: Stage 2: Back-End Derivation
A13: Derived variable | B13: How it is calculated | C13: Depends on
A14: wait_time | B14: current_time minus join_timestamp | C14: join_timestamp (auto)
A15: time_to_departure | B15: departure_time minus current_time | C15: flight_number > Flight API
A16: flight_status | B16: Flight API real-time response | C16: flight_number > Flight API
A17: estimated_stay | B17: min(max_stay_limit, TTD minus boarding_buffer) | C17: time_to_departure
A18: consecutive_skips | B18: Increments each time another entry is admitted | C18: admission event log
A19: value_per_person | B19: Revenue waterfall: deal > benefit card > default > neutral 50 | C19: access_program or membership_id
A20: total_group_value | B20: value_per_person x party_size | C20: value_per_person + party_size
A23: Stage 3: Lookup Table Normalization
A24: Dimension | B24: Raw input(s) | C24: Lookup table(s) | D24: Sub-score formula | E24: Output
A25: Capacity | B25: party_size, estimated_stay | C25: LT-Capacity: Party Size + Est Stay | D25: (PartyScore x 0.4) + (StayScore x 0.6) | E25: CapacityScore (0-100)
A26: Fairness | B26: wait_time, consecutive_skips | C26: LT-Fairness: Wait Time + Skips | D26: (WaitScore x 0.6) + (SkipScore x 0.4) | E26: FairnessScore (0-100)
A27: Urgency | B27: time_to_departure, flight_status | C27: LT-Urgency: TTD + Flight Status | D27: TTD_Score (modified by flight status) | E27: UrgencyScore (0-100)
A28: Revenue | B28: value_per_person | C28: LT-Revenue: Value/pp | D28: Value_Score (from lookup) | E28: RevenueScore (0-100)
A31: Stage 4: Weighted Composite Score
A32: PriModelScore = (W1 x RevenueScore) + (W2 x CapacityScore) + (W3 x FairnessScore) + (W4 x UrgencyScore)
A33: Weights are determined by the active Optimization Mode (Balanced, Revenue Focus, Efficiency Focus, Fairness First).
A34: Hard overrides bypass the score entirely: Max Wait (>60 min) = 999, Starvation Guard (>10 skips) = 998, Flight Departed = 0.
A36: Stage 5: Output to Staff
A37: Top 3 entries by PriModelScore are presented as suggestion cards.
A38: Each card shows: group info (program, party size), flight info (departure time, status badge), and a reasoning label (dominant dimension).
A39: Staff sees the recommendation. Staff decides whether to follow it or override.
A41: Concrete example: Group A from Scenario 1
A42: Stage | B42: Data | C42: Value
A43: 1. Front-end | B43: party_size | C43: 1
A44: 1. Front-end | B44: flight_number | C44: LA 635 (SCL, 4:10 PM)
A45: 1. Front-end | B45: access_program | C45: Priority Pass
A46: 2. Derivation | B46: wait_time | C46: 15 min
A47: 2. Derivation | B47: time_to_departure | C47: 50 min
A48: 2. Derivation | B48: estimated_stay | C48: 20 min (50 - 30 buffer)
A49: 2. Derivation | B49: value_per_person | C49: $27 (PP benefit card fee)
...

Sheet Capacity
A1: CAPACITY DIMENSION - Lookup Tables
A2: Lower seat-minutes = higher score = better for throughput
A4: Table 1: Party Size Score
A5: Party Size | B5: Capacity Score | C5: Rationale
A6: 1 | B6: 100 | C6: Solo = minimal seat consumption. Maximum throughput.
A7: 2 | B7: 85 | C7: Couple. Double the seats but still manageable.
A8: 3 | B8: 70 | C8: Small group. Meaningful capacity impact.
A9: 4 | B9: 55 | C9: Medium group. Significant seat consumption.
A10: 5 | B10: 40 | C10: Large group. High capacity cost.
A11: 6+ | B11: 25 | C11: Very large group. Near-maximum capacity penalty.
A13: Table 2: Party Size Score
A14: Pre book Party Size next 1 hour | B14: Capacity Score | C14: Rationale
A15: 6+ | B15: 100
A16: 5 | B16: 85
A17: 4 | B17: 70
A18: 3 | B18: 55
A19: 2 | B19: 40
A20: 1 | B20: 25
A21: Balanço entre quem esta entrando e quem esta saindo
A22: Table 3: Time to prebook
A23: Time to prebook (Min) | B23: Capacity Score | C23: Rationale
A24: 0-15 min | B24: 100
A25: 16-30 min | B25: 85
A26: 31-45 min | B26: 70
A27: 46-60 min | B27: 55
A28: 61-90 min | B28: 40
A29: 91-120 min | B29: 25
A31: Table 4: Estimated Stay Score
A32: Estimated Stay (min) | B32: Stay Score | C32: Rationale
A33: 0-20 min | B33: 100 | C33: Ultra-short visit. Seat frees almost immediately. Maximum throughput.
A34: 21-40 min | B34: 85 | C34: Short visit. Quick turnover.
A35: 41-60 min | B35: 70 | C35: Standard short visit. Good turnover.
A36: 61-90 min | B36: 55 | C36: Medium visit. Moderate capacity impact.
A37: 91-120 min | B37: 40 | C37: Long visit. Significant capacity consumption.
A38: 121-150 min | B38: 25 | C38: Very long visit. High capacity cost.
A39: 151-180 min | B39: 15 | C39: Maximum stay. Locks seat for extended period.
A40: 180+ min | B40: 10 | C40: Exceeds max stay limit. Capped at max_stay_limit.
A43: Composite Capacity Score
A44: CapacityScore = PartySize_Score *1 | B44: Phase 1
A45: CapacityScore = PartySize_Score *1 - prebooking
...

Sheet Urgency
A1: URGENCY DIMENSION - Lookup Tables
A2: Closer departure = higher score. NO TAPER. Short visits are optimal.
A4: Table 1: Time to Departure Score
A5: Design principle: a short visit is not penalized. The passenger uses their entitlement, the lounge collects the fee, the seat frees up fast. Everyone wins.
A7: Time to Departure (min) | B7: TTD Score | C7: Rationale
A8: 0-15 min | B8: 100 | C8: Imminent departure. Maximum urgency. Ultra-short visit = maximum throughput.
A9: 16-30 min | B9: 95 | C9: Very near departure. Quick visit, fast turnover.
A10: 31-45 min | B10: 90 | C10: Near departure. Short usable lounge time.
A11: 46-60 min | B11: 80 | C11: Within 1 hour. Strong urgency signal.
A12: 61-90 min | B12: 65 | C12: Moderate urgency. Standard lounge visit window.
A13: 91-120 min | B13: 45 | C13: Low-moderate urgency. Longer stay expected.
A14: 121-150 min | B14: 25 | C14: Low urgency. Extended stay.
A15: 151-180 min | B15: 10 | C15: Minimal urgency. Near max stay limit.
A16: 180+ min | B16: 0 | C16: No urgency. Flight is far. Urgency dimension contributes nothing.
A19: Table 2: Flight Status Modifier
A20: Flight Status | B20: Modifier | C20: Effect
A21: On Time | B21: x 1.0 | C21: Standard TTD score applies.
A22: Delayed | B22: Recalculate (~15min real time) - Scheduler | C22: Use new departure time. TTD score recalculated with updated time.
A23: Boarding | B23: =100 -> 100 | C23: Override to maximum urgency. Passenger should enter now or lose opportunity.
A24: Departed | B24: 0 | C24: Hard override: PriModelScore = 0. Entry removed from suggestions.
A25: Not Found | B25: =50 -> 50 | C25: Neutral. Flight data unavailable. No boost, no penalty.
A28: Composite Urgency Score
A29: UrgencyScore = TTD_Score (modified by Flight Status)
A30: Single-variable dimension. Flight status acts as modifier/override, not as a separate sub-score.

Sheet Fairness
A1: FAIRNESS DIMENSION - Lookup Tables
A2: Longer wait + more skips = higher score = higher priority
A4: Table 1: Wait Time Score
A5: Wait Time (min) | B5: Wait Score | C5: Rationale
A6: 0-5 min | B6: 10 | C6: Just arrived. Minimal fairness pressure.
A7: 6-10 min | B7: 20 | C7: Short wait. Low fairness signal.
A8: 11-15 min | B8: 30 | C8: Moderate short wait.
A9: 16-20 min | B9: 40 | C9: Getting noticeable.
A10: 21-25 min | B10: 50 | C10: Mid-range wait. Fairness starts mattering.
A11: 26-30 min | B11: 60 | C11: Significant wait. Passenger may be frustrated.
A12: 31-35 min | B12: 70 | C12: Long wait. Strong fairness signal.
A13: 36-40 min | B13: 80 | C13: Very long wait. High fairness pressure.
A14: 41-50 min | B14: 90 | C14: Approaching ceiling. Near-maximum priority.
A15: 51-60 min | B15: 95 | C15: Near hard override threshold.
A16: 60+ min | B16: 100 | C16: Hard override triggers at 60 min. Score = 999 (bypasses all weights).
A19: Table 2: Consecutive Skips Score
A20: Consecutive Skips | B20: Skip Score | C20: Rationale
A21: 0 | B21: 0 | C21: Not skipped. No starvation signal.
A22: 1 | B22: 15 | C22: Skipped once. Minimal concern.
A23: 2 | B23: 30 | C23: Skipped twice. Noticeable pattern.
A24: 3 | B24: 45 | C24: Three skips. Passenger may perceive unfairness.
A25: 4 | B25: 55 | C25: Four skips. Staff should be aware.
A26: 5 | B26: 65 | C26: Five skips. Strong starvation signal.
A27: 6 | B27: 75 | C27: Six skips. High priority boost.
A28: 7 | B28: 82 | C28: Seven skips. Very high starvation.
A29: 8 | B29: 90 | C29: Eight skips. Near override.
A30: 9 | B30: 95 | C30: Nine skips. Critical.
A31: 10+ | B31: 100 | C31: Starvation Guard triggers. Score = 998 (bypasses weights).
A34: Composite Fairness Score
A35: FairnessScore = (WaitTime_Score * 0.6) + (Skips_Score * 0.4)
A36: Wait time carries more weight. Skips add precision for cases where two groups waited the same time but one was actively bypassed.

Sheet Revenue
A1: REVENUE DIMENSION - Lookup Tables
A2: Higher total group value = higher score. Revenue is an upgrade, not a requirement.
A4: Table 1: Value Per Person Score (when access program is known)
A5: Value/pp ($) | B5: Value Score | C5: Example Program | D5: Rationale
A6: $35+ | B6: 100 | C6: Day Pass (walk-in) | D6: Full margin. No issuer deal. Maximum revenue per seat.
A7: $27-34 | B7: 80 | C7: Priority Pass ($27) | D7: Standard issuer deal. Strong revenue signal.
A8: $25-26 | B8: 70 | C8: Amex Platinum ($25) | D8: Issuer-negotiated. Good revenue.
A9: $20-24 | B9: 60 | C9: LoungeKey ($24) | D9: Standard deal. Moderate revenue.
A10: $15-19 | B10: 45 | C10: Low-value deal | D10: Below-average revenue per seat.
A11: $10-14 | B11: 30 | C11: Deep discount deal | D11: Low revenue. Capacity cost matters more.
A12: $0-9 | B12: 15 | C12: Complimentary / very low | D12: Near-zero revenue signal.
A13: Unknown | B13: 50 | C13: Access program not declared | D13: Neutral. No boost, no penalty. Other dimensions decide.
A16: Table 2: Party Size Revenue Multiplier
A17: Unlike Capacity (where bigger party = lower score), for Revenue bigger party = higher total value.
A18: Party Size | B18: Multiplier | C18: Example: PP at $27/pp | D18: Total Group Value
A19: 1 | B19: x 1.0 | C19: $27 x 1 | D19: $27
A20: 2 | B20: x 2.0 | C20: $27 x 2 | D20: $54
A21: 3 | B21: x 3.0 | C21: $27 x 3 | D21: $81
A22: 4 | B22: x 4.0 | C22: $27 x 4 | D22: $108
A23: 5 | B23: x 5.0 | C23: $27 x 5 | D23: $135
A26: Composite Revenue Score
A27: RevenueScore = Value_Score (from Table 1, based on value/pp or neutral 50 if unknown)
A28: Total Group Value = value/pp x party_size (used as context signal on suggestion cards, not directly in the score).
A29: Note: party_size already boosts Revenue implicitly through TotalGroupValue. At launch, with most entries lacking access program data, Revenue scores will be neutral (50) for the majority. The model works on 3 dimensions until revenue data coverage improves.
A31: Revenue Data Waterfall (best available source)
A32: Priority | B32: Source | C32: Phase | D32: Lookup
A33: Tier 1 | B33: Deal-based visit cost (membership ID > deal ID > visit cost) | C33: Phase 3 | D33: Use deal visit cost as value/pp
A34: Tier 2 | B34: Benefit card fee (access program > benefit card > fee) | C34: Phase 2 | D34: Use benefit card fee as value/pp
A35: Tier 3 | B35: Lounge default value per person (admin-configured) | C35: Phase 2 | D35: Use lounge.default_value_per_person
A36: Tier 4 | B36: No data available | C36: Phase 2 | D36: Score = 50 (neutral)
A38: What happens when access program is unknown (most entries at launch)
A39: When access program is not declared and no membership ID exists, the system falls through the revenue waterfall to Tier 4: neutral score of 50.
A40: Score 50 means: no boost, no penalty. The entry is not pushed to the bottom of the queue. It simply does not receive revenue-based differentiation.
A41: If all entries in the queue have Revenue = 50, the Revenue dimension contributes equally to all scores. The other three dimensions (Capacity, Fairness, Urgency) determine the ranking entirely.
A42: Revenue Focus mode without revenue data behaves like Balanced mode. The mode gains power as data coverage improves.

Sheet Hard Overrides
A1: HARD OVERRIDE RULES
A2: Binary rules that bypass the composite score entirely. No weight tuning changes these outcomes.
A4: Priority | B4: Override | C4: Trigger | D4: Effect | E4: Configurable Parameter
A5: 1 | B5: Max Wait | C5: wait_time > max_wait_hard_ceiling | D5: Score = 999. Forced to #1. | E5: max_wait_hard_ceiling (default: 60 min)
A6: 2 | B6: Starvation Guard | C6: consecutive_skips > max_consecutive_skips | D6: Score = 998. Forced to #1 (after Max Wait). | E6: max_consecutive_skips (default: 10)
A7: 3 | B7: Flight Departed | C7: flight_status = Departed | D7: Score = 0. Excluded from suggestions. | E7: N/A (automatic via Flight API)
A8: 4 | B8: Program Cap | C8: Last N admissions all same access_program | D8: Score x 0.5. Penalty, not override. | E8: program_cap_window (default: 3)
A11: Override precedence: Max Wait (999) > Starvation Guard (998) > Flight Departed (0) > Program Cap (x0.5)
A12: If Max Wait and Starvation Guard trigger simultaneously, Max Wait wins (higher score: 999 > 998).
A13: If Program Cap and Max Wait trigger simultaneously, Max Wait wins (hard override > penalty).

Sheet Data Degradation
A1: DATA DEGRADATION
A2: What happens when variables are missing
A4: Design principle: missing data produces neutral scores (50), never penalties.
A6: Dimension | B6: Data dependency | C6: What if missing? | D6: Fallback score | E6: Impact on ranking
A7: Revenue | B7: Access program, value/pp | C7: No revenue differentiation. All entries score the same. | D7: 50 (neutral) | E7: Other 3 dimensions decide. Most common scenario at launch.
A8: Capacity | B8: Party size (always known), flight departure | C8: If Flight API fails: use default_stay_estimate (120 min). Party size still differentiates. | D8: Lookup with default stay | E8: Minimal impact. Capacity still works with fallback.
A9: Fairness | B9: Wait time (always known), skips (always tracked) | C9: Never missing. Both signals are system-generated. | D9: N/A | E9: No impact. Most robust dimension.
A10: Urgency | B10: Flight departure time | C10: If Flight API fails entirely: neutral score. | D10: 50 (neutral) | E10: Rare. Flight number is mandatory in enrollment.
A13: What this means in practice
A14: Mode | B14: With full revenue data | C14: With revenue missing (most entries at launch)
